<?xml version="1.0"?>
<robot xmlns:xacro="http://ros.org/wiki/xacro">
  <xacro:macro name="robotiq_hande"  params="prefix">
    <link name="robotiq_hande_base_link">
      <inertial>
        <origin xyz="0 0 0.04607" rpy="0 0 0" />
        <mass value="0.86387" />
        <inertia ixx="1017560E-9" ixy="0" ixz="2235E-9" iyy="1028041E-9" iyz="0" izz="489810E-9" />
      </inertial>
      <visual>
        <origin xyz="0 0 0" rpy="0 0 0" />
        <geometry>
          <mesh filename="package://robotiq_hande_gripper_description/meshes/hand-e.dae" scale="0.001 0.001 0.001"/>
        </geometry>
        <material name="Gazebo/Black">
          <color rgba="0.1 0.1 0.1 1" />
        </material>
      </visual>
      <collision>
        <origin xyz="0 0 0" rpy="0 0 0" />
        <geometry>
          <mesh filename="package://robotiq_hande_gripper_description/meshes/hand-e.dae" scale="0.001 0.001 0.001"/>
        </geometry>
      </collision>
    </link>
    <gazebo reference="robotiq_hande_base_link">
      <material>Gazebo/Black</material>
      <selfCollide>False</selfCollide>
    </gazebo>

    <link name="left_finger">
      <inertial>
        <origin rpy="0 0 0" xyz="0.02262 -0.00759 0.00738"/>
        <mass value="0.03804"/>
        <inertia ixx="13567E-9" ixy="1849E-9" ixz="3622E-9" iyy="15784E-9" iyz="3616E-9" izz="7478E-9"/>
      </inertial>
      <visual>
        <origin rpy="0 0 0" xyz="0 0 0"/>
        <geometry>
          <mesh filename="package://robotiq_hande_gripper_description/meshes/finger_1.dae" scale="0.001 0.001 0.001"/>
        </geometry>
        <material name="Gazebo/Grey">
          <color rgba="0.1 0.1 0.1 1"/>
        </material>
      </visual>
      <collision>
        <origin rpy="0 0 0" xyz="0 0 0"/>
        <geometry>
          <mesh filename="package://robotiq_hande_gripper_description/meshes/finger_1.dae" scale="0.001 0.001 0.001"/>
        </geometry>
      </collision>
    </link>
    <gazebo reference="left_finger">
      <material>Gazebo/Grey</material>
      <selfCollide>False</selfCollide>
    </gazebo>

    <link name="right_finger">
      <inertial>
        <origin rpy="0 0 0" xyz="-0.02262 0.00759 0.00738"/>
        <mass value="0.03804"/>
        <inertia ixx="13567E-9" ixy="1849E-9" ixz="-3622E-9" iyy="15784E-9" iyz="-3616E-9" izz="7478E-9"/>
      </inertial>
      <visual>
        <origin rpy="0 0 0" xyz="0 0 0"/>
        <geometry>
          <mesh filename="package://robotiq_hande_gripper_description/meshes/finger_2.dae" scale="0.001 0.001 0.001"/>
        </geometry>
        <material name="Gazebo/Grey">
          <color rgba="0.1 0.1 0.1 1"/>
        </material>
      </visual>
      <collision>
        <origin rpy="0 0 0" xyz="0 0 0"/>
        <geometry>
          <mesh filename="package://robotiq_hande_gripper_description/meshes/finger_2.dae" scale="0.001 0.001 0.001"/>
        </geometry>
      </collision>
    </link>
    <gazebo reference="right_finger">
      <material>Gazebo/Grey</material>
      <selfCollide>False</selfCollide>
    </gazebo>

    <joint name="joint_finger" type="prismatic">
      <origin rpy="0 0 0" xyz="0 0 0.099"/>
      <parent link="robotiq_hande_base_link"/>
      <child link="left_finger"/>
      <axis xyz="-1 0 0"/>
      <limit effort="130" lower="0" upper="0.025" velocity="0.15"/>
    </joint>

    <joint name="robotiq_hande_base_to_right_finger" type="prismatic">
      <origin rpy="0 0 0" xyz="0 0 0.099"/>
      <parent link="robotiq_hande_base_link"/>
      <child link="right_finger"/>
      <axis xyz="1 0 0"/>
      <limit effort="130" lower="0" upper="0.025" velocity="0.15"/>
      <mimic joint="joint_finger" multiplier="1" offset="0"/>
    </joint>

    <gazebo>
      <plugin filename="librobotiq_gripper_gazebo_plugin.so" name="hrim_actuation_gripper_000000000004">
        <kp>100</kp>
        <ki>3</ki>
        <kd>9</kd>
        <joint>joint_finger</joint>
        <joint>robotiq_hande_base_to_right_finger</joint>
      </plugin>
      <plugin filename="libgazebo_ros_joint_state_publisher.so" name="mara_joint_state">
        <ros>
          <argument>~/out:=joint_states</argument>
        </ros>
        <update_rate>25</update_rate>
        <joint_name>joint_finger</joint_name>
      </plugin>
    </gazebo>
  </xacro:macro>
</robot>
