<?xml version="1.0"?>
<robot xmlns:xacro="http://ros.org/wiki/xacro">

  <xacro:macro name="robotiq_gripper"  params="prefix">
    <link name="robotiq_arg2f_base_link">
      <inertial>
        <origin xyz="8.625E-08 -4.6583E-06 0.03145" rpy="0 0 0" />
        <mass value="0.22652" />
        <inertia ixx="0.00020005" ixy="0" ixz="0" iyy="0.00017832" iyz="0" izz="0.00013478" />
      </inertial>
      <visual>
        <origin xyz="0 0 0" rpy="0 0 0" />
        <geometry>
          <mesh filename="package://robotiq_140_gripper_description/meshes/GRIPPER_base_axis.dae" scale="0.001 0.001 0.001"/>
        </geometry>
        <material name="Gazebo/Black">
          <color rgba="0.1 0.1 0.1 1" />
        </material>
      </visual>
      <collision>
        <origin xyz="0 0 0" rpy="0 0 0" />
        <geometry>
          <mesh filename="package://robotiq_140_gripper_description/meshes/GRIPPER_base_axis.dae" scale="0.001 0.001 0.001"/>
        </geometry>
      </collision>
    </link>
    <gazebo reference="robotiq_arg2f_base_link">
      <material>Gazebo/Black</material>
      <selfCollide>False</selfCollide>
    </gazebo>

    <link name="left_outer_knuckle">
      <inertial>
        <origin xyz="0 0 0" rpy="0 0 0" />
        <mass value="0.00853198276973456" />
        <inertia
            ixx="2.89328108496468E-06"
            ixy="-1.57935047237397E-19"
            ixz="-1.93980378593255E-19"
            iyy="1.86719750325683E-06"
            iyz="-1.21858577871576E-06"
            izz="1.21905238907251E-06" />
      </inertial>
      <visual>
        <origin xyz="0 0 0" rpy="0 0 0" />
        <geometry>
          <mesh filename="package://robotiq_140_gripper_description/meshes/robotiq_140_left_outer_knuckle.dae" scale="0.001 0.001 0.001"/>
        </geometry>
        <material name="">
          <color rgba="0.792156862745098 0.819607843137255 0.933333333333333 1" />
        </material>
      </visual>
      <collision>
        <origin xyz="0 0 0" rpy="0 0 0" />
        <geometry>
          <mesh filename="package://robotiq_140_gripper_description/meshes/robotiq_140_left_outer_knuckle.dae" scale="0.001 0.001 0.001"/>
        </geometry>
      </collision>
    </link>
    <gazebo reference="left_outer_knuckle">
      <material>Gazebo/Grey</material>
      <selfCollide>False</selfCollide>
    </gazebo>

    <link name="right_outer_knuckle">
      <inertial>
        <origin xyz="0 0 0" rpy="0 0 0" />
        <mass value="0.00853198276973456" />
        <inertia
            ixx="2.89328108496468E-06"
            ixy="-1.57935047237397E-19"
            ixz="-1.93980378593255E-19"
            iyy="1.86719750325683E-06"
            iyz="-1.21858577871576E-06"
            izz="1.21905238907251E-06" />
      </inertial>
      <visual>
        <origin xyz="0 0 0" rpy="0 0 0" />
        <geometry>
          <mesh filename="package://robotiq_140_gripper_description/meshes/robotiq_140_right_outer_knuckle.dae" scale="0.001 0.001 0.001"/>
        </geometry>
        <material name="">
          <color rgba="0.792156862745098 0.819607843137255 0.933333333333333 1" />
        </material>
      </visual>
      <collision>
        <origin xyz="0 0 0" rpy="0 0 0" />
        <geometry>
          <mesh filename="package://robotiq_140_gripper_description/meshes/robotiq_140_right_outer_knuckle.dae" scale="0.001 0.001 0.001"/>
        </geometry>
      </collision>
    </link>
    <gazebo reference="right_outer_knuckle">
      <material>Gazebo/Grey</material>
      <selfCollide>False</selfCollide>
    </gazebo>

    <link name="left_inner_knuckle">
      <inertial>
        <origin xyz="0.000123011831763771 0.0507850843201817 0.00103968640075166" rpy="0 0 0" />
        <mass value="0.0271177346495152" />
        <inertia
            ixx="2.61910379223783E-05"
            ixy="-2.43616858946494E-07"
            ixz="-6.37789906117123E-09"
            iyy="2.8270243746167E-06"
            iyz="-5.37200748039765E-07"
            izz="2.83695868220296E-05" />
      </inertial>
      <visual>
        <origin xyz="0 0 0" rpy="0 0 0" />
        <geometry>
          <mesh filename="package://robotiq_140_gripper_description/meshes/robotiq_140_left_inner_knuckle.dae" scale="0.001 0.001 0.001"/>
        </geometry>
        <material name="Gazebo/Black">
          <color rgba="0.1 0.1 0.1 1" />
        </material>
      </visual>
    </link>
    <gazebo reference="left_inner_knuckle">
      <material>Gazebo/Black</material>
      <selfCollide>False</selfCollide>
    </gazebo>

    <link name="right_inner_knuckle">
      <inertial>
        <origin xyz="0.000123011831763771 0.0507850843201817 0.00103968640075166" rpy="0 0 0" />
        <mass value="0.0271177346495152" />
        <inertia
            ixx="2.61910379223783E-05"
            ixy="-2.43616858946494E-07"
            ixz="-6.37789906117123E-09"
            iyy="2.8270243746167E-06"
            iyz="-5.37200748039765E-07"
            izz="2.83695868220296E-05" />
      </inertial>
      <visual>
        <origin xyz="0 0 0" rpy="0 0 0" />
        <geometry>
          <mesh filename="package://robotiq_140_gripper_description/meshes/robotiq_140_right_inner_knuckle.dae" scale="0.001 0.001 0.001"/>
        </geometry>
        <material name="Gazebo/Black">
          <color rgba="0.1 0.1 0.1 1" />
        </material>
      </visual>

    </link>
    <gazebo reference="right_inner_knuckle">
      <material>Gazebo/Black</material>
      <selfCollide>False</selfCollide>
    </gazebo>

    <link name="left_inner_finger">
      <inertial>
        <origin xyz="0.0 0.031506174 -0.017648840" rpy="0 0 0" />
        <mass value="0.0104003125914103" />
        <inertia
            ixx="2.71909453810972E-06"
            ixy="1.35402465472579E-21"
            ixz="-7.1817349065269E-22"
            iyy="7.69100314106116E-07"
            iyz="6.74715432769696E-07"
            izz="2.30315190420171E-06" />
      </inertial>
      <visual>
        <origin xyz="0 0 0" rpy="0 0 0" />
        <geometry>
          <mesh filename="package://robotiq_140_gripper_description/meshes/robotiq_140_left_inner_finger.dae" scale="0.001 0.001 0.001" />
        </geometry>
        <material name="Gazebo/Black">
          <color rgba="0.1 0.1 0.1 1" />
        </material>
      </visual>
      <collision>
        <origin xyz="0 0 0" rpy="0 0 0" />
        <geometry>
          <mesh filename="package://robotiq_140_gripper_description/meshes/robotiq_140_left_inner_finger.dae" scale="0.001 0.001 0.001" />
        </geometry>
      </collision>
    </link>
    <gazebo reference="left_inner_finger">
      <material>Gazebo/Black</material>
      <selfCollide>False</selfCollide>
    </gazebo>

    <link name="right_inner_finger">
      <inertial>
        <origin xyz="0.0 0.031506174 -0.017648840" rpy="0 0 0" />
        <mass value="0.0104003125914103" />
        <inertia
            ixx="2.71909453810972E-06"
            ixy="1.35402465472579E-21"
            ixz="-7.1817349065269E-22"
            iyy="7.69100314106116E-07"
            iyz="6.74715432769696E-07"
            izz="2.30315190420171E-06" />
      </inertial>
      <visual>
        <origin xyz="0 0 0" rpy="0 0 0" />
        <geometry>
          <mesh filename="package://robotiq_140_gripper_description/meshes/robotiq_140_right_inner_finger.dae" scale="0.001 0.001 0.001"/>
        </geometry>
        <material name="Gazebo/Black">
          <color rgba="0.1 0.1 0.1 1" />
        </material>
      </visual>
      <collision>
        <origin xyz="0 0 0" rpy="0 0 0" />
        <geometry>
          <mesh filename="package://robotiq_140_gripper_description/meshes/robotiq_140_right_inner_finger.dae" scale="0.001 0.001 0.001"/>
        </geometry>
      </collision>
    </link>
    <gazebo reference="right_inner_finger">
      <material>Gazebo/Black</material>
      <selfCollide>False</selfCollide>
    </gazebo>

    <link name="left_outer_finger">
      <inertial>
        <origin xyz="0.00030115855001899 0.0373907951953854 -0.0208027427000385" rpy="0 0 0" />
        <mass value="0.022614240507152" />
        <inertia
            ixx="1.52518312458174E-05"
            ixy="9.76583423954399E-10"
            ixz="-5.43838577022588E-10"
            iyy="6.17694243867776E-06"
            iyz="6.78636130740228E-06"
            izz="1.16494917907219E-05" />
      </inertial>
      <visual>
        <origin xyz="0 0 0" rpy="0 0 0" />
        <geometry>
          <mesh filename="package://robotiq_140_gripper_description/meshes/robotiq_140_left_outer_finger.dae" scale="0.001 0.001 0.001"/>
        </geometry>
        <material name="Gazebo/Black">
          <color rgba="0.1 0.1 0.1 1" />
        </material>
      </visual>
      <collision>
        <origin xyz="0 0 0" rpy="0 0 0" />
        <geometry>
          <mesh filename="package://robotiq_140_gripper_description/meshes/robotiq_140_left_outer_finger.dae" scale="0.001 0.001 0.001"/>
        </geometry>
      </collision>
    </link>
    <gazebo reference="left_outer_finger">
      <material>Gazebo/Black</material>
      <selfCollide>False</selfCollide>
    </gazebo>

    <link name="right_outer_finger">
      <inertial>
        <origin xyz="0.00030115855001899 0.0373907951953854 -0.0208027427000385" rpy="0 0 0" />
        <mass value="0.022614240507152" />
        <inertia
            ixx="1.52518312458174E-05"
            ixy="9.76583423954399E-10"
            ixz="-5.43838577022588E-10"
            iyy="6.17694243867776E-06"
            iyz="6.78636130740228E-06"
            izz="1.16494917907219E-05" />
      </inertial>
      <visual>
        <origin xyz="0 0 0" rpy="0 0 0" />
        <geometry>
          <mesh filename="package://robotiq_140_gripper_description/meshes/robotiq_140_right_outer_finger.dae" scale="0.001 0.001 0.001"/>
        </geometry>
        <material name="Gazebo/Black">
          <color rgba="0.1 0.1 0.1 1" />
        </material>
      </visual>
      <collision>
        <origin xyz="0 0 0" rpy="0 0 0" />
        <geometry>
          <mesh filename="package://robotiq_140_gripper_description/meshes/robotiq_140_right_outer_finger.dae" scale="0.001 0.001 0.001"/>
        </geometry>
      </collision>
    </link>
    <gazebo reference="right_outer_finger">
      <material>Gazebo/Black</material>
      <selfCollide>False</selfCollide>
    </gazebo>

    <joint name="robotiq_arg2f_base_to_left_outer_knuckle" type="revolute">
      <origin xyz="0.0306 0 0.05466" rpy="0 0 0" />
      <parent link="robotiq_arg2f_base_link" />
      <child link="left_outer_knuckle" />
      <axis xyz="0 -1 0" />
      <limit lower="0" upper="0.78574722925"  velocity="2.0" effort="1000" />
      <mimic joint="joint_finger" multiplier="1" offset="0"/>
    </joint>

    <joint name="joint_finger" type="revolute">
      <origin xyz="-0.0306 0 0.05466" rpy="0 0 0" />
      <parent link="robotiq_arg2f_base_link" />
      <child link="right_outer_knuckle" />
      <axis xyz="0 1 0" />
      <limit lower="0" upper="0.78574722925" velocity="2.0" effort="1000" />
    </joint>

    <joint name="robotiq_arg2f_base_to_left_inner_knuckle" type="revolute">
      <origin xyz="0.0127 0 0.06118" rpy="0 0 0" />
      <parent link="robotiq_arg2f_base_link" />
      <child link="left_inner_knuckle" />
      <axis xyz="0 -1 0" />
      <limit lower="0" upper="0.78574722925" velocity="2.0" effort="1000" />
      <mimic joint="joint_finger" multiplier="1" offset="0"/>
    </joint>

    <joint name="robotiq_arg2f_base_to_right_inner_knuckle" type="revolute">
      <origin xyz="-0.0127 0 0.06118" rpy="0 0 0" />
      <parent link="robotiq_arg2f_base_link" />
      <child link="right_inner_knuckle" />
      <axis xyz="0 1 0" />
      <limit lower="0" upper="0.78574722925" velocity="2.0" effort="1000" />
      <mimic joint="joint_finger" multiplier="1" offset="0"/>
    </joint>

    <joint name="left_outer_knuckle_to_finger" type="fixed">
      <origin xyz="0.03142 0 -0.00453" rpy="0 0 0" />
      <parent link="left_outer_knuckle" />
      <child link="left_outer_finger" />
    </joint>

    <joint name="right_outer_knuckle_to_finger" type="fixed">
      <origin xyz="-0.03142 0 -0.00453" rpy="0 0 0" />
      <parent link="right_outer_knuckle" />
      <child link="right_outer_finger" />
    </joint>

    <joint name="left_outer_finger_to_inner" type="revolute">
      <origin xyz="0.03543 0 0.0789" rpy="0 0 0" />
      <parent link="left_outer_finger" />
      <child link="left_inner_finger" />
      <axis xyz="0 -1 0" />
      <limit lower="0" upper="0.78574722925" velocity="2.0" effort="1000" />
      <mimic joint="joint_finger" multiplier="1" offset="0"/>
    </joint>

    <joint name="right_outer_finger_to_inner" type="revolute">
      <origin xyz="-0.03543 0 0.0789" rpy="0 0 0" />
      <parent link="right_outer_finger" />
      <child link="right_inner_finger" />
      <axis xyz="0 1 0" />
      <limit lower="0" upper="0.78574722925" velocity="2.0" effort="1000" />
      <mimic joint="joint_finger" multiplier="1" offset="0"/>
    </joint>

    <gazebo>
      <joint name="left_inner_knuckle_to_finger" type="revolute">
        <pose frame="">0.06686 0 0.07436 0 0 0</pose>
        <parent>${prefix}::left_inner_knuckle</parent>
        <child>${prefix}::left_inner_finger</child>
        <axis>
          <xyz>0 -1 0</xyz>
          <limit>
            <lower>0</lower>
            <upper>0.78574722925</upper>
            <velocity>2.0</velocity>
            <effort>1000</effort>
          </limit>
        </axis>
      </joint>

      <joint name="right_inner_knuckle_to_finger" type="revolute">
        <pose frame="">-0.06686 0 0.07436 0 0 0</pose>
        <parent>${prefix}::right_inner_knuckle</parent>
        <child>${prefix}::right_inner_finger</child>
        <axis>
          <xyz>0 1 0</xyz>
          <limit>
            <lower>0</lower>
            <upper>0.78574722925</upper>
            <velocity>2.0</velocity>
            <effort>1000</effort>
          </limit>
        </axis>
      </joint>

      <plugin filename="librobotiq_gripper_gazebo_plugin.so" name="hrim_actuation_gripper_000000000004">
        <joint>robotiq_arg2f_base_to_left_inner_knuckle</joint>
        <joint>robotiq_arg2f_base_to_left_outer_knuckle</joint>
        <joint>robotiq_arg2f_base_to_right_inner_knuckle</joint>
        <joint>joint_finger</joint>
      </plugin>
      <plugin filename="libgazebo_ros_joint_state_publisher.so" name="mara_joint_state">
        <ros>
          <argument>~/out:=joint_states</argument>
        </ros>
        <update_rate>25</update_rate>
        <joint_name>joint_finger</joint_name>
      </plugin>
    </gazebo>

  </xacro:macro>
</robot>
