<?xml version="1.0" ?>
<!-- =================================================================================== -->
<!-- |    This document was autogenerated by xacro from ros2_mara_ws/src/robotiq_modular_gripper/robotiq_140_gripper_description/urdf/robotiq_140_world.urdf.xacro | -->
<!-- |    EDITING THIS FILE BY HAND IS NOT RECOMMENDED                                 | -->
<!-- =================================================================================== -->
<robot name="robotiq_gripper" xmlns:xacro="http://ros.org/wiki/xacro">
  <link name="robotiq_140_robotiq_arg2f_base_link">
    <inertial>
      <origin rpy="0 0 0" xyz="-0.00013 0.00011 0.03284"/>
      <mass value="0.52954"/>
      <inertia ixx="573495E-9" ixy="-554E-9" ixz="2628E-9" iyy="681780E-9" iyz="607E-9" izz="483281E-9"/>
    </inertial>
    <visual>
      <origin rpy="0 0 0" xyz="0 0 0"/>
      <geometry>
        <mesh filename="package://robotiq_140_gripper_description/meshes/GRIPPER_base_axis.dae" scale="0.001 0.001 0.001"/>
      </geometry>
      <material name="Gazebo/Black">
        <color rgba="0.1 0.1 0.1 1"/>
      </material>
    </visual>
    <collision>
      <origin rpy="0 0 0" xyz="0 0 0"/>
      <geometry>
        <mesh filename="package://robotiq_140_gripper_description/meshes/GRIPPER_base_axis.dae" scale="0.001 0.001 0.001"/>
      </geometry>
    </collision>
  </link>
  <gazebo reference="robotiq_140_robotiq_arg2f_base_link">
    <material>Gazebo/Black</material>
    <selfCollide>True</selfCollide>
  </gazebo>
  <link name="robotiq_140_left_outer_knuckle">
    <inertial>
      <origin rpy="0 0 0" xyz="0.01616 0 -0.00133"/>
      <mass value="0.0131"/>
      <inertia ixx="325.5E-9" ixy="0" ixz="197.94E-9" iyy="2306.36E-9" iyz="0" izz="2176E-9"/>
    </inertial>
    <visual>
      <origin rpy="0 0 0" xyz="0 0 0"/>
      <geometry>
        <mesh filename="package://robotiq_140_gripper_description/meshes/robotiq_140_left_outer_knuckle.dae" scale="0.001 0.001 0.001"/>
      </geometry>
      <material name="">
        <color rgba="0.792156862745098 0.819607843137255 0.933333333333333 1"/>
      </material>
    </visual>
    <collision>
      <origin rpy="0 0 0" xyz="0 0 0"/>
      <geometry>
        <mesh filename="package://robotiq_140_gripper_description/meshes/robotiq_140_left_outer_knuckle.dae" scale="0.001 0.001 0.001"/>
      </geometry>
    </collision>
  </link>
  <gazebo reference="robotiq_140_left_outer_knuckle">
    <material>Gazebo/Grey</material>
    <selfCollide>True</selfCollide>
  </gazebo>
  <link name="robotiq_140_right_outer_knuckle">
    <inertial>
      <origin rpy="0 0 0" xyz="-0.01616 0 -0.00133"/>
      <mass value="0.0131"/>
      <inertia ixx="325.5E-9" ixy="0" ixz="-197.94E-9" iyy="2306.36E-9" iyz="0" izz="2176E-9"/>
    </inertial>
    <visual>
      <origin rpy="0 0 0" xyz="0 0 0"/>
      <geometry>
        <mesh filename="package://robotiq_140_gripper_description/meshes/robotiq_140_right_outer_knuckle.dae" scale="0.001 0.001 0.001"/>
      </geometry>
      <material name="">
        <color rgba="0.792156862745098 0.819607843137255 0.933333333333333 1"/>
      </material>
    </visual>
    <collision>
      <origin rpy="0 0 0" xyz="0 0 0"/>
      <geometry>
        <mesh filename="package://robotiq_140_gripper_description/meshes/robotiq_140_right_outer_knuckle.dae" scale="0.001 0.001 0.001"/>
      </geometry>
    </collision>
  </link>
  <gazebo reference="robotiq_140_right_outer_knuckle">
    <material>Gazebo/Grey</material>
    <selfCollide>True</selfCollide>
  </gazebo>
  <link name="robotiq_140_left_inner_knuckle">
    <inertial>
      <origin rpy="0 0 0" xyz="0.03332 0 0.0379"/>
      <mass value="0.04476"/>
      <inertia ixx="28054E-9" ixy="0" ixz="-19174E-9" iyy="39758E-9" iyz="0" izz="23453E-9"/>
    </inertial>
    <visual>
      <origin rpy="0 0 0" xyz="0 0 0"/>
      <geometry>
        <mesh filename="package://robotiq_140_gripper_description/meshes/robotiq_140_left_inner_knuckle.dae" scale="0.001 0.001 0.001"/>
      </geometry>
      <material name="Gazebo/Black">
        <color rgba="0.1 0.1 0.1 1"/>
      </material>
    </visual>
    <collision>
      <origin rpy="0 0 0" xyz="0 0 0"/>
      <geometry>
        <mesh filename="package://robotiq_140_gripper_description/meshes/robotiq_140_left_inner_knuckle.dae" scale="0.001 0.001 0.001"/>
      </geometry>
    </collision>
  </link>
  <gazebo reference="robotiq_140_left_inner_knuckle">
    <material>Gazebo/Black</material>
    <selfCollide>False</selfCollide>
  </gazebo>
  <link name="robotiq_140_right_inner_knuckle">
    <inertial>
      <origin rpy="0 0 0" xyz="-0.03332 0 0.0379"/>
      <mass value="0.04476"/>
      <inertia ixx="28054E-9" ixy="0" ixz="19174E-9" iyy="39758E-9" iyz="0" izz="23453E-9"/>
    </inertial>
    <visual>
      <origin rpy="0 0 0" xyz="0 0 0"/>
      <geometry>
        <mesh filename="package://robotiq_140_gripper_description/meshes/robotiq_140_right_inner_knuckle.dae" scale="0.001 0.001 0.001"/>
      </geometry>
      <material name="Gazebo/Black">
        <color rgba="0.1 0.1 0.1 1"/>
      </material>
    </visual>
    <collision>
      <origin rpy="0 0 0" xyz="0 0 0"/>
      <geometry>
        <mesh filename="package://robotiq_140_gripper_description/meshes/robotiq_140_right_inner_knuckle.dae" scale="0.001 0.001 0.001"/>
      </geometry>
    </collision>
  </link>
  <gazebo reference="robotiq_140_right_inner_knuckle">
    <material>Gazebo/Black</material>
    <selfCollide>False</selfCollide>
  </gazebo>
  <link name="robotiq_140_left_inner_finger">
    <inertial>
      <origin rpy="0 0 0" xyz="-0.01563 0 0.02522"/>
      <mass value="0.045"/>
      <inertia ixx="26663E-9" ixy="0" ixz="5579E-9" iyy="28009E-9" iyz="0" izz="4368E-9"/>
    </inertial>
    <visual>
      <origin rpy="0 0 0" xyz="0 0 0"/>
      <geometry>
        <mesh filename="package://robotiq_140_gripper_description/meshes/robotiq_140_left_inner_finger.dae" scale="0.001 0.001 0.001"/>
      </geometry>
      <material name="Gazebo/Black">
        <color rgba="0.1 0.1 0.1 1"/>
      </material>
    </visual>
    <collision>
      <origin rpy="0 0 0" xyz="0 0 0"/>
      <geometry>
        <mesh filename="package://robotiq_140_gripper_description/meshes/robotiq_140_left_inner_finger.dae" scale="0.001 0.001 0.001"/>
      </geometry>
    </collision>
  </link>
  <gazebo reference="robotiq_140_left_inner_finger">
    <material>Gazebo/Black</material>
    <selfCollide>False</selfCollide>
  </gazebo>
  <link name="robotiq_140_right_inner_finger">
    <inertial>
      <origin rpy="0 0 0" xyz="0.01563 0 0.02522"/>
      <mass value="0.045"/>
      <inertia ixx="26663E-9" ixy="0" ixz="-5579E-9" iyy="28009E-9" iyz="0" izz="4368E-9"/>
    </inertial>
    <visual>
      <origin rpy="0 0 0" xyz="0 0 0"/>
      <geometry>
        <mesh filename="package://robotiq_140_gripper_description/meshes/robotiq_140_right_inner_finger.dae" scale="0.001 0.001 0.001"/>
      </geometry>
      <material name="Gazebo/Black">
        <color rgba="0.1 0.1 0.1 1"/>
      </material>
    </visual>
    <collision>
      <origin rpy="0 0 0" xyz="0 0 0"/>
      <geometry>
        <mesh filename="package://robotiq_140_gripper_description/meshes/robotiq_140_right_inner_finger.dae" scale="0.001 0.001 0.001"/>
      </geometry>
    </collision>
  </link>
  <gazebo reference="robotiq_140_right_inner_finger">
    <material>Gazebo/Black</material>
    <selfCollide>False</selfCollide>
  </gazebo>
  <link name="robotiq_140_left_outer_finger">
    <inertial>
      <origin rpy="0 0 0" xyz="0.01482 0 0.03451"/>
      <mass value="0.07637"/>
      <inertia ixx="45513E-9" ixy="0" ixz="-20691E-9" iyy="52570E-9" iyz="0" izz="17804E-9"/>
    </inertial>
    <visual>
      <origin rpy="0 0 0" xyz="0 0 0"/>
      <geometry>
        <mesh filename="package://robotiq_140_gripper_description/meshes/robotiq_140_left_outer_finger.dae" scale="0.001 0.001 0.001"/>
      </geometry>
      <material name="Gazebo/Black">
        <color rgba="0.1 0.1 0.1 1"/>
      </material>
    </visual>
    <collision>
      <origin rpy="0 0 0" xyz="0 0 0"/>
      <geometry>
        <mesh filename="package://robotiq_140_gripper_description/meshes/robotiq_140_left_outer_finger.dae" scale="0.001 0.001 0.001"/>
      </geometry>
    </collision>
  </link>
  <gazebo reference="robotiq_140_left_outer_finger">
    <material>Gazebo/Black</material>
    <selfCollide>True</selfCollide>
  </gazebo>
  <link name="robotiq_140_right_outer_finger">
    <inertial>
      <origin rpy="0 0 0" xyz="-0.01482 0 0.03451"/>
      <mass value="0.07637"/>
      <inertia ixx="45513E-9" ixy="0" ixz="20691E-9" iyy="52570E-9" iyz="0" izz="17804E-9"/>
    </inertial>
    <visual>
      <origin rpy="0 0 0" xyz="0 0 0"/>
      <geometry>
        <mesh filename="package://robotiq_140_gripper_description/meshes/robotiq_140_right_outer_finger.dae" scale="0.001 0.001 0.001"/>
      </geometry>
      <material name="Gazebo/Black">
        <color rgba="0.1 0.1 0.1 1"/>
      </material>
    </visual>
    <collision>
      <origin rpy="0 0 0" xyz="0 0 0"/>
      <geometry>
        <mesh filename="package://robotiq_140_gripper_description/meshes/robotiq_140_right_outer_finger.dae" scale="0.001 0.001 0.001"/>
      </geometry>
    </collision>
  </link>
  <gazebo reference="robotiq_140_right_outer_finger">
    <material>Gazebo/Black</material>
    <selfCollide>True</selfCollide>
  </gazebo>
  <joint name="robotiq_arg2f_base_to_robotiq_140_left_outer_knuckle" type="revolute">
    <origin rpy="0 0 0" xyz="0.0306 0 0.05466"/>
    <parent link="robotiq_140_robotiq_arg2f_base_link"/>
    <child link="robotiq_140_left_outer_knuckle"/>
    <axis xyz="0 -1 0"/>
    <limit effort="18.65" lower="0" upper="0.78574722925" velocity="2.0"/>
    <mimic joint="robotiq_140_joint_finger" multiplier="1" offset="0"/>
  </joint>
  <joint name="robotiq_140_joint_finger" type="revolute">
    <origin rpy="0 0 0" xyz="-0.0306 0 0.05466"/>
    <parent link="robotiq_140_robotiq_arg2f_base_link"/>
    <child link="robotiq_140_right_outer_knuckle"/>
    <axis xyz="0 1 0"/>
    <limit effort="18.65" lower="0" upper="0.78574722925" velocity="3.54"/>
  </joint>
  <joint name="robotiq_arg2f_base_to_robotiq_140_left_inner_knuckle" type="revolute">
    <origin rpy="0 0 0" xyz="0.0127 0 0.06118"/>
    <parent link="robotiq_140_robotiq_arg2f_base_link"/>
    <child link="robotiq_140_left_inner_knuckle"/>
    <axis xyz="0 -1 0"/>
    <limit effort="18.65" lower="0" upper="0.78574722925" velocity="3.54"/>
    <mimic joint="robotiq_140_joint_finger" multiplier="1" offset="0"/>
  </joint>
  <joint name="robotiq_arg2f_base_to_robotiq_140_right_inner_knuckle" type="revolute">
    <origin rpy="0 0 0" xyz="-0.0127 0 0.06118"/>
    <parent link="robotiq_140_robotiq_arg2f_base_link"/>
    <child link="robotiq_140_right_inner_knuckle"/>
    <axis xyz="0 1 0"/>
    <limit effort="18.65" lower="0" upper="0.78574722925" velocity="3.54"/>
    <mimic joint="robotiq_140_joint_finger" multiplier="1" offset="0"/>
  </joint>
  <joint name="robotiq_140_left_outer_knuckle_to_finger" type="fixed">
    <origin rpy="0 0 0" xyz="0.03142 0 -0.00453"/>
    <parent link="robotiq_140_left_outer_knuckle"/>
    <child link="robotiq_140_left_outer_finger"/>
  </joint>
  <joint name="robotiq_140_right_outer_knuckle_to_finger" type="fixed">
    <origin rpy="0 0 0" xyz="-0.03142 0 -0.00453"/>
    <parent link="robotiq_140_right_outer_knuckle"/>
    <child link="robotiq_140_right_outer_finger"/>
  </joint>
  <joint name="robotiq_140_left_outer_finger_to_inner" type="revolute">
    <origin rpy="0 0 0" xyz="0.03543 0 0.0789"/>
    <parent link="robotiq_140_left_outer_finger"/>
    <child link="robotiq_140_left_inner_finger"/>
    <axis xyz="0 1 0"/>
    <limit effort="18.65" lower="0" upper="0.78574722925" velocity="3.54"/>
    <mimic joint="robotiq_140_joint_finger" multiplier="1" offset="0"/>
  </joint>
  <joint name="robotiq_140_right_outer_finger_to_inner" type="revolute">
    <origin rpy="0 0 0" xyz="-0.03543 0 0.0789"/>
    <parent link="robotiq_140_right_outer_finger"/>
    <child link="robotiq_140_right_inner_finger"/>
    <axis xyz="0 -1 0"/>
    <limit effort="18.65" lower="0" upper="0.78574722925" velocity="3.54"/>
    <mimic joint="robotiq_140_joint_finger" multiplier="1" offset="0"/>
  </joint>
  <gazebo>
    <joint name="robotiq_140_left_inner_knuckle_to_finger" type="revolute">
      <pose frame="">-0.0179 0 0.00652 0 0 0</pose>
      <parent>robotiq_140_left_inner_knuckle</parent>
      <child>robotiq_140_left_inner_finger</child>
      <axis>
        <xyz>0 1 0</xyz>
        <limit>
          <lower>0</lower>
          <upper>0.78574722925</upper>
          <velocity>3.54</velocity>
          <effort>18.65</effort>
        </limit>
      </axis>
    </joint>
    <joint name="robotiq_140_right_inner_knuckle_to_finger" type="revolute">
      <pose frame="">0.0179 0 0.00652 0 0 0</pose>
      <parent>robotiq_140_right_inner_knuckle</parent>
      <child>robotiq_140_right_inner_finger</child>
      <axis>
        <xyz>0 -1 0</xyz>
        <limit>
          <lower>0</lower>
          <upper>0.78574722925</upper>
          <velocity>3.54</velocity>
          <effort>18.65</effort>
        </limit>
      </axis>
    </joint>
    <plugin filename="librobotiq_gripper_gazebo_plugin.so" name="hrim_actuator_gripper_000000000004">
      <kp>600</kp>
      <ki>0.1</ki>
      <kd>0.01</kd>
      <min_velocity>30</min_velocity>
      <max_velocity>250</max_velocity>
      <radius>156</radius>
      <joint>robotiq_arg2f_base_to_robotiq_140_left_inner_knuckle</joint>
      <joint>robotiq_arg2f_base_to_robotiq_140_left_outer_knuckle</joint>
      <joint>robotiq_arg2f_base_to_robotiq_140_right_inner_knuckle</joint>
      <joint>robotiq_140_joint_finger</joint>
    </plugin>
  </gazebo>
  <link name="world"/>
  <joint name="world_to_robotiq_adapter" type="fixed">
    <origin rpy="0 0 0" xyz="0 0 0.5"/>
    <parent link="world"/>
    <child link="robotiq_140_robotiq_arg2f_base_link"/>
  </joint>
  <gazebo>
    <plugin filename="libgazebo_ros_joint_state_publisher.so" name="robotiq_140_joint_state">
      <ros>
        <argument>~/out:=robotiq_140_joint_states</argument>
      </ros>
      <update_rate>25</update_rate>
      <joint_name>robotiq_140_joint_finger</joint_name>
    </plugin>
  </gazebo>
</robot>
