<?xml version="1.0" ?>
<!-- =================================================================================== -->
<!-- |    This document was autogenerated by xacro from ros2_mara_ws/src/robotiq_modular_gripper/robotiq_85_gripper_description/urdf/robotiq_85_world.urdf.xacro | -->
<!-- |    EDITING THIS FILE BY HAND IS NOT RECOMMENDED                                 | -->
<!-- =================================================================================== -->
<robot name="robotiq_85" xmlns:xacro="http://ros.org/wiki/xacro">
  <link name="robotiq_85_robotiq_arg2f_base_link">
    <inertial>
      <origin rpy="0 0 0" xyz="-0.00013 -0.00011 0.03284"/>
      <mass value="0.55938"/>
      <inertia ixx="605783E-9" ixy="-579.95E-9" ixz="2765.53E-9" iyy="720148E-9" iyz="618E-9" izz="510534E-9"/>
    </inertial>
    <visual>
      <origin rpy="0 0 0" xyz="0 0 0"/>
      <geometry>
        <mesh filename="package://robotiq_85_gripper_description/meshes/base_gripper.dae" scale="0.001 0.001 0.001"/>
      </geometry>
      <material name="Gazebo/Black">
        <color rgba="0.1 0.1 0.1 1"/>
      </material>
    </visual>
    <collision>
      <origin rpy="0 0 0" xyz="0 0 0"/>
      <geometry>
        <mesh filename="package://robotiq_85_gripper_description/meshes/base_gripper.dae" scale="0.001 0.001 0.001"/>
      </geometry>
    </collision>
  </link>
  <gazebo reference="robotiq_85_robotiq_arg2f_base_link">
    <material>Gazebo/Black</material>
    <selfCollide>True</selfCollide>
  </gazebo>
  <link name="robotiq_85_left_outer_knuckle">
    <inertial>
      <origin rpy="0 0 0" xyz="0.01545 0 -0.00118"/>
      <mass value="0.01252"/>
      <inertia ixx="312.44E-9" ixy="0" ixz="-168.09E-9" iyy="2156E-9" iyz="0" izz="2027.51E-9"/>
    </inertial>
    <visual>
      <origin rpy="0 0 0" xyz="0 0 0"/>
      <geometry>
        <mesh filename="package://robotiq_85_gripper_description/meshes/2-F-85_1_l.dae" scale="0.001 0.001 0.001"/>
      </geometry>
      <material name="Gazebo/Grey">
        <color rgba="0.1 0.1 0.1 1"/>
      </material>
    </visual>
    <collision>
      <origin rpy="0 0 0" xyz="0 0 0"/>
      <geometry>
        <mesh filename="package://robotiq_85_gripper_description/meshes/2-F-85_1_l.dae" scale="0.001 0.001 0.001"/>
      </geometry>
    </collision>
  </link>
  <gazebo reference="robotiq_85_left_outer_knuckle">
    <material>Gazebo/Grey</material>
    <selfCollide>True</selfCollide>
  </gazebo>
  <link name="robotiq_85_right_outer_knuckle">
    <inertial>
      <origin rpy="0 0 0" xyz="-0.01545 0 -0.00118"/>
      <mass value="0.01252"/>
      <inertia ixx="312.44E-9" ixy="0" ixz="-168.09E-9" iyy="2156E-9" iyz="0" izz="2027.51E-9"/>
    </inertial>
    <visual>
      <origin rpy="0 0 0" xyz="0 0 0"/>
      <geometry>
        <mesh filename="package://robotiq_85_gripper_description/meshes/2-F-85_1_r.dae" scale="0.001 0.001 0.001"/>
      </geometry>
      <material name="Gazebo/Grey">
        <color rgba="0.1 0.1 0.1 1"/>
      </material>
    </visual>
    <collision>
      <origin rpy="0 0 0" xyz="0 0 0"/>
      <geometry>
        <mesh filename="package://robotiq_85_gripper_description/meshes/2-F-85_1_r.dae" scale="0.001 0.001 0.001"/>
      </geometry>
    </collision>
  </link>
  <gazebo reference="robotiq_85_right_outer_knuckle">
    <material>Gazebo/Grey</material>
    <selfCollide>True</selfCollide>
  </gazebo>
  <link name="robotiq_85_left_outer_finger">
    <inertial>
      <origin rpy="0 0 0" xyz="0.004 0 0.01892"/>
      <mass value="0.03848"/>
      <inertia ixx="12341E-9" ixy="0" ixz="-2152.21E-9" iyy="10617E-9" iyz="0" izz="4812.09E-9"/>
    </inertial>
    <visual>
      <origin rpy="0 0 0" xyz="0 0 0"/>
      <geometry>
        <mesh filename="package://robotiq_85_gripper_description/meshes/2-F-85_3_l.dae" scale="0.001 0.001 0.001"/>
      </geometry>
      <material name="Gazebo/Black">
        <color rgba="0.1 0.1 0.1 1"/>
      </material>
    </visual>
    <collision>
      <origin rpy="0 0 0" xyz="0 0 0"/>
      <geometry>
        <mesh filename="package://robotiq_85_gripper_description/meshes/2-F-85_3_l.dae" scale="0.001 0.001 0.001"/>
      </geometry>
    </collision>
  </link>
  <gazebo reference="robotiq_85_left_outer_finger">
    <material>Gazebo/Black</material>
    <selfCollide>True</selfCollide>
  </gazebo>
  <link name="robotiq_85_right_outer_finger">
    <inertial>
      <origin rpy="0 0 0" xyz="-0.004 0 0.01892"/>
      <mass value="0.03848"/>
      <inertia ixx="12341E-9" ixy="0" ixz="-2152.21E-9" iyy="10617E-9" iyz="0" izz="4812.09E-9"/>
    </inertial>
    <visual>
      <origin rpy="0 0 0" xyz="0 0 0"/>
      <geometry>
        <mesh filename="package://robotiq_85_gripper_description/meshes/2-F-85_3_r.dae" scale="0.001 0.001 0.001"/>
      </geometry>
      <material name="Gazebo/Black">
        <color rgba="0.1 0.1 0.1 1"/>
      </material>
    </visual>
    <collision>
      <origin rpy="0 0 0" xyz="0 0 0"/>
      <geometry>
        <mesh filename="package://robotiq_85_gripper_description/meshes/2-F-85_3_r.dae" scale="0.001 0.001 0.001"/>
      </geometry>
    </collision>
  </link>
  <gazebo reference="robotiq_85_right_outer_finger">
    <material>Gazebo/Black</material>
    <selfCollide>True</selfCollide>
  </gazebo>
  <link name="robotiq_85_left_inner_knuckle">
    <inertial>
      <origin rpy="0 0 0" xyz="0.01952 0 0.022"/>
      <mass value="0.02731"/>
      <inertia ixx="8621.3E-9" ixy="0" ixz="-3646.49E-9" iyy="8004.28E-9" iyz="0" izz="7704.42E-9"/>
    </inertial>
    <visual>
      <origin rpy="0 0 0" xyz="0 0 0"/>
      <geometry>
        <mesh filename="package://robotiq_85_gripper_description/meshes/2-F-85_2_l.dae" scale="0.001 0.001 0.001"/>
      </geometry>
      <material name="Gazebo/Black">
        <color rgba="0.1 0.1 0.1 1"/>
      </material>
    </visual>
    <collision>
      <origin rpy="0 0 0" xyz="0 0 0"/>
      <geometry>
        <mesh filename="package://robotiq_85_gripper_description/meshes/2-F-85_2_l.dae" scale="0.001 0.001 0.001"/>
      </geometry>
    </collision>
  </link>
  <gazebo reference="robotiq_85_left_inner_knuckle">
    <material>Gazebo/Black</material>
    <selfCollide>False</selfCollide>
  </gazebo>
  <link name="robotiq_85_right_inner_knuckle">
    <inertial>
      <origin rpy="0 0 0" xyz="-0.01952 0 0.022"/>
      <mass value="0.02731"/>
      <inertia ixx="8621.3E-9" ixy="0" ixz="3646.49E-9" iyy="8004.28E-9" iyz="0" izz="7704.42E-9"/>
    </inertial>
    <visual>
      <origin rpy="0 0 0" xyz="0 0 0"/>
      <geometry>
        <mesh filename="package://robotiq_85_gripper_description/meshes/2-F-85_2_r.dae" scale="0.001 0.001 0.001"/>
      </geometry>
      <material name="Gazebo/Black">
        <color rgba="0.1 0.1 0.1 1"/>
      </material>
    </visual>
    <collision>
      <origin rpy="0 0 0" xyz="0 0 0"/>
      <geometry>
        <mesh filename="package://robotiq_85_gripper_description/meshes/2-F-85_2_r.dae" scale="0.001 0.001 0.001"/>
      </geometry>
    </collision>
  </link>
  <gazebo reference="robotiq_85_right_inner_knuckle">
    <material>Gazebo/Black</material>
    <selfCollide>False</selfCollide>
  </gazebo>
  <link name="robotiq_85_left_inner_finger">
    <inertial>
      <origin rpy="0 0 0" xyz="-0.01409 0 0.01569"/>
      <mass value="0.037"/>
      <inertia ixx="12446.57E-9" ixy="0" ixz="4167.81E-9" iyy="14201.18E-9" iyz="0" izz="4979.86E-9"/>
    </inertial>
    <visual>
      <origin rpy="0 0 0" xyz="0 0 0"/>
      <geometry>
        <mesh filename="package://robotiq_85_gripper_description/meshes/2-F-85_4_l.dae" scale="0.001 0.001 0.001"/>
      </geometry>
      <material name="Gazebo/Black">
        <color rgba="0.1 0.1 0.1 1"/>
      </material>
    </visual>
    <collision>
      <origin rpy="0 0 0" xyz="0 0 0"/>
      <geometry>
        <mesh filename="package://robotiq_85_gripper_description/meshes/2-F-85_4_l.dae" scale="0.001 0.001 0.001"/>
      </geometry>
    </collision>
  </link>
  <gazebo reference="robotiq_85_left_inner_finger">
    <material>Gazebo/Black</material>
    <selfCollide>False</selfCollide>
  </gazebo>
  <link name="robotiq_85_right_inner_finger">
    <inertial>
      <origin rpy="0 0 0" xyz="0.01409 0 0.01569"/>
      <mass value="0.037"/>
      <inertia ixx="12446.57E-9" ixy="0" ixz="-4167.81E-9" iyy="14201.18E-9" iyz="0" izz="4979.86E-9"/>
    </inertial>
    <visual>
      <origin rpy="0 0 0" xyz="0 0 0"/>
      <geometry>
        <mesh filename="package://robotiq_85_gripper_description/meshes/2-F-85_4_r.dae" scale="0.001 0.001 0.001"/>
      </geometry>
      <material name="Gazebo/Black">
        <color rgba="0.1 0.1 0.1 1"/>
      </material>
    </visual>
    <collision>
      <origin rpy="0 0 0" xyz="0 0 0"/>
      <geometry>
        <mesh filename="package://robotiq_85_gripper_description/meshes/2-F-85_4_r.dae" scale="0.001 0.001 0.001"/>
      </geometry>
    </collision>
  </link>
  <gazebo reference="robotiq_85_right_inner_finger">
    <material>Gazebo/Black</material>
    <selfCollide>False</selfCollide>
  </gazebo>
  <joint name="robotiq_85_robotiq_arg2f_base_link_to_robotiq_85_left_outer_knuckle" type="revolute">
    <origin rpy="0 0 0" xyz="0.0306 0 0.05466"/>
    <parent link="robotiq_85_robotiq_arg2f_base_link"/>
    <child link="robotiq_85_left_outer_knuckle"/>
    <axis xyz="0 -1 0"/>
    <limit effort="21.03" lower="0" upper="0.82589" velocity="3.87"/>
    <mimic joint="robotiq_85_joint_finger" multiplier="1" offset="0"/>
  </joint>
  <joint name="robotiq_85_joint_finger" type="revolute">
    <origin rpy="0 0 0" xyz="-0.0306 0 0.05466"/>
    <parent link="robotiq_85_robotiq_arg2f_base_link"/>
    <child link="robotiq_85_right_outer_knuckle"/>
    <axis xyz="0 1 0"/>
    <limit effort="21.03" lower="0" upper="0.82589" velocity="3.87"/>
  </joint>
  <joint name="robotiq_85_robotiq_arg2f_base_link_to_robotiq_85_left_inner_knuckle" type="revolute">
    <origin rpy="0 0 0" xyz="0.0127 0 0.06118"/>
    <parent link="robotiq_85_robotiq_arg2f_base_link"/>
    <child link="robotiq_85_left_inner_knuckle"/>
    <axis xyz="0 -1 0"/>
    <limit effort="21.03" lower="0" upper="0.82589" velocity="3.87"/>
    <mimic joint="robotiq_85_joint_finger" multiplier="1" offset="0"/>
  </joint>
  <joint name="robotiq_85_robotiq_arg2f_base_link_to_robotiq_85_right_inner_knuckle" type="revolute">
    <origin rpy="0 0 0" xyz="-0.0127 0 0.06118"/>
    <parent link="robotiq_85_robotiq_arg2f_base_link"/>
    <child link="robotiq_85_right_inner_knuckle"/>
    <axis xyz="0 1 0"/>
    <limit effort="21.03" lower="0" upper="0.82589" velocity="3.87"/>
    <mimic joint="robotiq_85_joint_finger" multiplier="1" offset="0"/>
  </joint>
  <joint name="robotiq_85_left_outer_finger_to_inner" type="revolute">
    <origin rpy="0 0 0" xyz="0.00678 0 0.04703"/>
    <parent link="robotiq_85_left_outer_finger"/>
    <child link="robotiq_85_left_inner_finger"/>
    <axis xyz="0 1 0"/>
    <limit effort="21.03" lower="0" upper="0.82589" velocity="3.87"/>
    <mimic joint="robotiq_85_joint_finger" multiplier="1" offset="0"/>
  </joint>
  <joint name="robotiq_85_right_outer_finger_to_inner" type="revolute">
    <origin rpy="0 0 0" xyz="-0.00678 0 0.04703"/>
    <parent link="robotiq_85_right_outer_finger"/>
    <child link="robotiq_85_right_inner_finger"/>
    <axis xyz="0 -1 0"/>
    <limit effort="21.03" lower="0" upper="0.82589" velocity="3.87"/>
    <mimic joint="robotiq_85_joint_finger" multiplier="1" offset="0"/>
  </joint>
  <joint name="robotiq_85_left_outer_knuckle_to_finger" type="fixed">
    <origin rpy="0 0 0" xyz="0.03142 0 -0.00453"/>
    <parent link="robotiq_85_left_outer_knuckle"/>
    <child link="robotiq_85_left_outer_finger"/>
  </joint>
  <joint name="robotiq_85_right_outer_knuckle_to_finger" type="fixed">
    <origin rpy="0 0 0" xyz="-0.03142 0 -0.00453"/>
    <parent link="robotiq_85_right_outer_knuckle"/>
    <child link="robotiq_85_right_outer_finger"/>
  </joint>
  <gazebo>
    <joint name="robotiq_85_left_inner_knuckle_to_finger" type="revolute">
      <pose frame="">-0.0179 0 0.00652 0 0 0</pose>
      <parent>robotiq_85_left_inner_knuckle</parent>
      <child>robotiq_85_left_inner_finger</child>
      <axis>
        <xyz>0 1 0</xyz>
        <limit>
          <lower>0</lower>
          <upper>0.82589</upper>
          <velocity>3.87</velocity>
          <effort>21.03</effort>
        </limit>
      </axis>
    </joint>
    <joint name="robotiq_85_right_inner_knuckle_to_finger" type="revolute">
      <pose frame="">0.0179 0 0.00652 0 0 0</pose>
      <parent>robotiq_85_right_inner_knuckle</parent>
      <child>robotiq_85_right_inner_finger</child>
      <axis>
        <xyz>0 -1 0</xyz>
        <limit>
          <lower>0</lower>
          <upper>0.82589</upper>
          <velocity>3.87</velocity>
          <effort>21.03</effort>
        </limit>
      </axis>
    </joint>
    <plugin filename="librobotiq_gripper_gazebo_plugin.so" name="hrim_actuator_gripper_000000000004">
      <kp>10</kp>
      <ki>10</ki>
      <kd>0.1</kd>
      <min_velocity>20</min_velocity>
      <max_velocity>150</max_velocity>
      <radius>100</radius>
      <joint>robotiq_85_robotiq_arg2f_base_link_to_robotiq_85_left_inner_knuckle</joint>
      <joint>robotiq_85_robotiq_arg2f_base_link_to_robotiq_85_left_outer_knuckle</joint>
      <joint>robotiq_85_robotiq_arg2f_base_link_to_robotiq_85_right_inner_knuckle</joint>
      <joint>robotiq_85_joint_finger</joint>
    </plugin>
  </gazebo>
  <link name="world"/>
  <joint name="world_to_robotiq_arg2f_base" type="fixed">
    <origin rpy="0 0 0" xyz="0 0 0.5"/>
    <parent link="world"/>
    <child link="robotiq_85_robotiq_arg2f_base_link"/>
  </joint>
  <gazebo>
    <plugin filename="libgazebo_ros_joint_state_publisher.so" name="robotiq_85_joint_state">
      <ros>
        <argument>~/out:=robotiq_85_joint_states</argument>
      </ros>
      <update_rate>25</update_rate>
      <joint_name>robotiq_85_joint_finger</joint_name>
    </plugin>
  </gazebo>
</robot>
