<?xml version="1.0" ?>
<!-- =================================================================================== -->
<!-- |    This document was autogenerated by xacro from /home/erle/ros2_mara_ws/src/robotiq_modular_gripper/robotiq_85_gripper_description/urdf/robotiq_85_hros_support.urdf.xacro | -->
<!-- |    EDITING THIS FILE BY HAND IS NOT RECOMMENDED                                 | -->
<!-- =================================================================================== -->
<robot name="robotiq_85" xmlns:xacro="http://ros.org/wiki/xacro">
  <link name="robotiq_arg2f_base">
    <inertial>
      <origin rpy="0 0 0" xyz="8.625E-08 -4.6583E-06 0.03145"/>
      <mass value="0.22652"/>
      <inertia ixx="0.00020005" ixy="0" ixz="0" iyy="0.00017832" iyz="0" izz="0.00013478"/>
    </inertial>
    <visual>
      <origin rpy="0 0 0" xyz="0 0 0"/>
      <geometry>
        <mesh filename="package://robotiq_85_gripper_description/meshes/base_gripper.dae" scale="0.001 0.001 0.001"/>
      </geometry>
      <material name="Gazebo/Black">
        <color rgba="0.1 0.1 0.1 1"/>
      </material>
    </visual>
    <collision>
      <origin rpy="0 0 0" xyz="0 0 0"/>
      <geometry>
        <mesh filename="package://robotiq_85_gripper_description/meshes/base_gripper.dae" scale="0.001 0.001 0.001"/>
      </geometry>
    </collision>
  </link>
  <gazebo reference="robotiq_arg2f_base">
    <material>Gazebo/Black</material>
    <selfCollide>True</selfCollide>
  </gazebo>
  <link name="left_outer_knuckle">
    <inertial>
      <origin rpy="0 0 0" xyz="8.625E-08 -4.6583E-06 0.03145"/>
      <mass value="0.22652"/>
      <inertia ixx="0.00020005" ixy="0" ixz="0" iyy="0.00017832" iyz="0" izz="0.00013478"/>
    </inertial>
    <visual>
      <origin rpy="0 0 0" xyz="0 0 0"/>
      <geometry>
        <mesh filename="package://robotiq_85_gripper_description/meshes/2-F-85_1_l.dae" scale="0.001 0.001 0.001"/>
      </geometry>
      <material name="Gazebo/Grey">
        <color rgba="0.1 0.1 0.1 1"/>
      </material>
    </visual>
    <collision>
      <origin rpy="0 0 0" xyz="0 0 0"/>
      <geometry>
        <mesh filename="package://robotiq_85_gripper_description/meshes/2-F-85_1_l.dae" scale="0.001 0.001 0.001"/>
      </geometry>
    </collision>
  </link>
  <gazebo reference="left_outer_knuckle">
    <material>Gazebo/Grey</material>
    <selfCollide>True</selfCollide>
  </gazebo>
  <link name="right_outer_knuckle">
    <inertial>
      <origin rpy="0 0 0" xyz="8.625E-08 -4.6583E-06 0.03145"/>
      <mass value="0.22652"/>
      <inertia ixx="0.00020005" ixy="0" ixz="0" iyy="0.00017832" iyz="0" izz="0.00013478"/>
    </inertial>
    <visual>
      <origin rpy="0 0 0" xyz="0 0 0"/>
      <geometry>
        <mesh filename="package://robotiq_85_gripper_description/meshes/2-F-85_1_r.dae" scale="0.001 0.001 0.001"/>
      </geometry>
      <material name="Gazebo/Grey">
        <color rgba="0.1 0.1 0.1 1"/>
      </material>
    </visual>
    <collision>
      <origin rpy="0 0 0" xyz="0 0 0"/>
      <geometry>
        <mesh filename="package://robotiq_85_gripper_description/meshes/2-F-85_1_r.dae" scale="0.001 0.001 0.001"/>
      </geometry>
    </collision>
  </link>
  <gazebo reference="right_outer_knuckle">
    <material>Gazebo/Grey</material>
    <selfCollide>True</selfCollide>
  </gazebo>
  <link name="left_outer_finger">
    <inertial>
      <origin rpy="0 0 0" xyz="8.625E-08 -4.6583E-06 0.03145"/>
      <mass value="0.22652"/>
      <inertia ixx="0.00020005" ixy="0" ixz="0" iyy="0.00017832" iyz="0" izz="0.00013478"/>
    </inertial>
    <visual>
      <origin rpy="0 0 0" xyz="0 0 0"/>
      <geometry>
        <mesh filename="package://robotiq_85_gripper_description/meshes/2-F-85_3_l.dae" scale="0.001 0.001 0.001"/>
      </geometry>
      <material name="Gazebo/Black">
        <color rgba="0.1 0.1 0.1 1"/>
      </material>
    </visual>
    <collision>
      <origin rpy="0 0 0" xyz="0 0 0"/>
      <geometry>
        <mesh filename="package://robotiq_85_gripper_description/meshes/2-F-85_3_l.dae" scale="0.001 0.001 0.001"/>
      </geometry>
    </collision>
  </link>
  <gazebo reference="left_outer_finger">
    <material>Gazebo/Black</material>
    <selfCollide>True</selfCollide>
  </gazebo>
  <link name="right_outer_finger">
    <inertial>
      <origin rpy="0 0 0" xyz="8.625E-08 -4.6583E-06 0.03145"/>
      <mass value="0.22652"/>
      <inertia ixx="0.00020005" ixy="0" ixz="0" iyy="0.00017832" iyz="0" izz="0.00013478"/>
    </inertial>
    <visual>
      <origin rpy="0 0 0" xyz="0 0 0"/>
      <geometry>
        <mesh filename="package://robotiq_85_gripper_description/meshes/2-F-85_3_r.dae" scale="0.001 0.001 0.001"/>
      </geometry>
      <material name="Gazebo/Black">
        <color rgba="0.1 0.1 0.1 1"/>
      </material>
    </visual>
    <collision>
      <origin rpy="0 0 0" xyz="0 0 0"/>
      <geometry>
        <mesh filename="package://robotiq_85_gripper_description/meshes/2-F-85_3_r.dae" scale="0.001 0.001 0.001"/>
      </geometry>
    </collision>
  </link>
  <gazebo reference="right_outer_finger">
    <material>Gazebo/Black</material>
    <selfCollide>True</selfCollide>
  </gazebo>
  <link name="left_inner_knuckle">
    <inertial>
      <origin rpy="0 0 0" xyz="8.625E-08 -4.6583E-06 0.03145"/>
      <mass value="0.22652"/>
      <inertia ixx="0.00020005" ixy="0" ixz="0" iyy="0.00017832" iyz="0" izz="0.00013478"/>
    </inertial>
    <visual>
      <origin rpy="0 0 0" xyz="0 0 0"/>
      <geometry>
        <mesh filename="package://robotiq_85_gripper_description/meshes/2-F-85_2_l.dae" scale="0.001 0.001 0.001"/>
      </geometry>
      <material name="Gazebo/Black">
        <color rgba="0.1 0.1 0.1 1"/>
      </material>
    </visual>
    <collision>
      <origin rpy="0 0 0" xyz="0 0 0"/>
      <geometry>
        <mesh filename="package://robotiq_85_gripper_description/meshes/2-F-85_2_l.dae" scale="0.001 0.001 0.001"/>
      </geometry>
    </collision>
  </link>
  <gazebo reference="left_inner_knuckle">
    <material>Gazebo/Black</material>
    <selfCollide>True</selfCollide>
  </gazebo>
  <link name="right_inner_knuckle">
    <inertial>
      <origin rpy="0 0 0" xyz="8.625E-08 -4.6583E-06 0.03145"/>
      <mass value="0.22652"/>
      <inertia ixx="0.00020005" ixy="0" ixz="0" iyy="0.00017832" iyz="0" izz="0.00013478"/>
    </inertial>
    <visual>
      <origin rpy="0 0 0" xyz="0 0 0"/>
      <geometry>
        <mesh filename="package://robotiq_85_gripper_description/meshes/2-F-85_2_r.dae" scale="0.001 0.001 0.001"/>
      </geometry>
      <material name="Gazebo/Black">
        <color rgba="0.1 0.1 0.1 1"/>
      </material>
    </visual>
    <collision>
      <origin rpy="0 0 0" xyz="0 0 0"/>
      <geometry>
        <mesh filename="package://robotiq_85_gripper_description/meshes/2-F-85_2_r.dae" scale="0.001 0.001 0.001"/>
      </geometry>
    </collision>
  </link>
  <gazebo reference="right_inner_knuckle">
    <material>Gazebo/Black</material>
    <selfCollide>True</selfCollide>
  </gazebo>
  <link name="left_inner_finger">
    <inertial>
      <origin rpy="0 0 0" xyz="8.625E-08 -4.6583E-06 0.03145"/>
      <mass value="0.22652"/>
      <inertia ixx="0.00020005" ixy="0" ixz="0" iyy="0.00017832" iyz="0" izz="0.00013478"/>
    </inertial>
    <visual>
      <origin rpy="0 0 0" xyz="0 0 0"/>
      <geometry>
        <mesh filename="package://robotiq_85_gripper_description/meshes/2-F-85_4_l.dae" scale="0.001 0.001 0.001"/>
      </geometry>
      <material name="Gazebo/Black">
        <color rgba="0.1 0.1 0.1 1"/>
      </material>
    </visual>
    <collision>
      <origin rpy="0 0 0" xyz="0 0 0"/>
      <geometry>
        <mesh filename="package://robotiq_85_gripper_description/meshes/2-F-85_4_l.dae" scale="0.001 0.001 0.001"/>
      </geometry>
    </collision>
  </link>
  <gazebo reference="left_inner_finger">
    <material>Gazebo/Black</material>
    <selfCollide>True</selfCollide>
  </gazebo>
  <link name="right_inner_finger">
    <inertial>
      <origin rpy="0 0 0" xyz="8.625E-08 -4.6583E-06 0.03145"/>
      <mass value="0.22652"/>
      <inertia ixx="0.00020005" ixy="0" ixz="0" iyy="0.00017832" iyz="0" izz="0.00013478"/>
    </inertial>
    <visual>
      <origin rpy="0 0 0" xyz="0 0 0"/>
      <geometry>
        <mesh filename="package://robotiq_85_gripper_description/meshes/2-F-85_4_r.dae" scale="0.001 0.001 0.001"/>
      </geometry>
      <material name="Gazebo/Black">
        <color rgba="0.1 0.1 0.1 1"/>
      </material>
    </visual>
    <collision>
      <origin rpy="0 0 0" xyz="0 0 0"/>
      <geometry>
        <mesh filename="package://robotiq_85_gripper_description/meshes/2-F-85_4_r.dae" scale="0.001 0.001 0.001"/>
      </geometry>
    </collision>
  </link>
  <gazebo reference="right_inner_finger">
    <material>Gazebo/Black</material>
    <selfCollide>True</selfCollide>
  </gazebo>
  <joint name="left_outer_knuckle_joint" type="revolute">
    <origin rpy="0 0 0" xyz="-0.0306 0 0.05490"/>
    <parent link="robotiq_arg2f_base"/>
    <child link="left_outer_knuckle"/>
    <axis xyz="0 1 0"/>
    <limit effort="1000" lower="0.0" upper="0.78" velocity="2.0"/>
    <mimic joint="joint_finger" multiplier="1" offset="0"/>
  </joint>
  <joint name="joint_finger" type="revolute">
    <origin rpy="0 0 3.1416" xyz="0.0306 0 0.05490"/>
    <parent link="robotiq_arg2f_base"/>
    <child link="right_outer_knuckle"/>
    <axis xyz="0 1 0"/>
    <limit effort="1000" lower="0" upper="0.78" velocity="2.0"/>
  </joint>
  <joint name="left_inner_knuckle_joint" type="revolute">
    <origin rpy="0 0 0" xyz="-0.0127 0 0.06142"/>
    <parent link="robotiq_arg2f_base"/>
    <child link="left_inner_knuckle"/>
    <axis xyz="0 1 0"/>
    <limit effort="1000" lower="0" upper="0.8757" velocity="2.0"/>
    <mimic joint="joint_finger" multiplier="1" offset="0"/>
  </joint>
  <joint name="right_inner_knuckle_joint" type="revolute">
    <origin rpy="0 0 3.1416" xyz="0.0127 0 0.06142"/>
    <parent link="robotiq_arg2f_base"/>
    <child link="right_inner_knuckle"/>
    <axis xyz="0 1 0"/>
    <limit effort="1000" lower="0" upper="0.8757" velocity="2.0"/>
    <mimic joint="joint_finger" multiplier="1" offset="0"/>
  </joint>
  <joint name="left_inner_finger_joint" type="revolute">
    <origin rpy="0 0.0 0" xyz="-0.005625 0 0.04718"/>
    <parent link="left_outer_finger"/>
    <child link="left_inner_finger"/>
    <axis xyz="0 -1 0"/>
    <limit effort="1000" lower="0" upper="0.775" velocity="2.0"/>
    <mimic joint="joint_finger" multiplier="1" offset="0"/>
  </joint>
  <joint name="right_inner_finger_joint" type="revolute">
    <origin rpy="0 0 0" xyz="-0.005625 0 0.04718"/>
    <parent link="right_outer_finger"/>
    <child link="right_inner_finger"/>
    <axis xyz="0 -1 0"/>
    <limit effort="1000" lower="0" upper="0.775" velocity="2.0"/>
    <mimic joint="joint_finger" multiplier="1" offset="0"/>
  </joint>
  <joint name="left_outer_finger_joint" type="fixed">
    <origin rpy="0 0 0" xyz="-0.03156 0 -0.003758"/>
    <parent link="left_outer_knuckle"/>
    <child link="left_outer_finger"/>
  </joint>
  <joint name="right_outer_finger_joint" type="fixed">
    <origin rpy="0 0 0" xyz="-0.03156 0 -0.003758"/>
    <parent link="right_outer_knuckle"/>
    <child link="right_outer_finger"/>
  </joint>
  <gazebo>
    <joint name="left_finger_joint2" type="revolute">
      <pose frame="">0.017901 0 0.00651469 0 0 0</pose>
      <parent>robotiq85::left_inner_knuckle</parent>
      <child>robotiq85::left_inner_finger</child>
      <axis>
        <xyz>0 -1 0</xyz>
        <limit>
          <lower>-0.8</lower>
          <upper>0.8</upper>
          <velocity>2.0</velocity>
          <effort>1000</effort>
        </limit>
      </axis>
    </joint>
    <joint name="right_finger_joint2" type="revolute">
      <pose frame="">0.017901 0 0.00651469 0 0 0</pose>
      <parent>robotiq85::right_inner_knuckle</parent>
      <child>robotiq85::right_inner_finger</child>
      <axis>
        <xyz>0 1 0</xyz>
        <limit>
          <lower>-0.8</lower>
          <upper>0.8</upper>
          <velocity>2.0</velocity>
          <effort>1000</effort>
        </limit>
      </axis>
    </joint>
    <plugin filename="librobotiq_gripper_gazebo_plugin.so" name="robotiq_85_gripper">
      <left_joint>left_inner_knuckle_joint</left_joint>
      <left_joint>left_outer_knuckle_joint</left_joint>
      <right_joint>right_inner_knuckle_joint</right_joint>
      <right_joint>joint_finger</right_joint>
    </plugin>
  </gazebo>
  <link name="world"/>
  <link name="robotiq_adapter_link">
    <inertial>
      <origin rpy="0 0 0" xyz="8.625E-08 -4.6583E-06 0.03145"/>
      <mass value="0.22652"/>
      <inertia ixx="0.00020005" ixy="0" ixz="0" iyy="0.00017832" iyz="0" izz="0.00013478"/>
    </inertial>
    <visual>
      <origin rpy="0 0 1.57" xyz="0 0 0"/>
      <geometry>
        <mesh filename="package://robotiq_140_gripper_description/meshes/hros_robotiq_adapter.dae" scale="0.001 0.001 0.001"/>
      </geometry>
      <material name="Gazebo/Black">
        <color rgba="0.1 0.1 0.1 1"/>
      </material>
    </visual>
    <collision>
      <origin rpy="0 0 1.57" xyz="0 0 0"/>
      <geometry>
        <mesh filename="package://robotiq_140_gripper_description/meshes/hros_robotiq_adapter.dae" scale="0.001 0.001 0.001"/>
      </geometry>
    </collision>
  </link>
  <gazebo reference="robotiq_adapter_link">
    <material>Gazebo/Black</material>
    <selfCollide>False</selfCollide>
  </gazebo>
  <joint name="base_adapter_to_base_robotiq_joint" type="fixed">
    <origin rpy="0 0 0" xyz=" 0 0 0.03653"/>
    <parent link="robotiq_adapter_link"/>
    <child link="robotiq_arg2f_base"/>
  </joint>
  <joint name="world_to_hande_joint" type="fixed">
    <origin rpy="0 0 0" xyz="0 0 0.5"/>
    <parent link="world"/>
    <child link="robotiq_adapter_link"/>
  </joint>
  <gazebo>
    <plugin filename="libgazebo_ros_joint_state_publisher.so" name="mara_joint_state">
      <ros>
        <argument>~/out:=joint_states</argument>
      </ros>
      <update_rate>25</update_rate>
      <joint_name>joint_finger</joint_name>
    </plugin>
  </gazebo>
</robot>
